[2024-03-18T20:54:21.516+0000] {logging_mixin.py:154} INFO - Changing /opt/***/logs/dag_id=recalls_etl_v1/run_id=manual__2024-03-18T20:54:19.547344+00:00/task_id=get_raw_data permission to 509
[2024-03-18T20:54:21.547+0000] {logging_mixin.py:154} INFO - Changing /opt/***/logs/dag_id=recalls_etl_v1/run_id=manual__2024-03-18T20:54:19.547344+00:00/task_id=get_raw_data permission to 509
[2024-03-18T20:54:21.581+0000] {taskinstance.py:1159} INFO - Dependencies all met for dep_context=non-requeueable deps ti=<TaskInstance: recalls_etl_v1.get_raw_data manual__2024-03-18T20:54:19.547344+00:00 [queued]>
[2024-03-18T20:54:21.590+0000] {taskinstance.py:1159} INFO - Dependencies all met for dep_context=requeueable deps ti=<TaskInstance: recalls_etl_v1.get_raw_data manual__2024-03-18T20:54:19.547344+00:00 [queued]>
[2024-03-18T20:54:21.591+0000] {taskinstance.py:1361} INFO - Starting attempt 1 of 1
[2024-03-18T20:54:21.606+0000] {taskinstance.py:1382} INFO - Executing <Task(PythonOperator): get_raw_data> on 2024-03-18 20:54:19.547344+00:00
[2024-03-18T20:54:21.611+0000] {standard_task_runner.py:57} INFO - Started process 119 to run task
[2024-03-18T20:54:21.614+0000] {standard_task_runner.py:84} INFO - Running: ['***', 'tasks', 'run', 'recalls_etl_v1', 'get_raw_data', 'manual__2024-03-18T20:54:19.547344+00:00', '--job-id', '18', '--raw', '--subdir', 'DAGS_FOLDER/recalls_etl_v1.py', '--cfg-path', '/tmp/tmpv8bbvj8v']
[2024-03-18T20:54:21.616+0000] {standard_task_runner.py:85} INFO - Job 18: Subtask get_raw_data
[2024-03-18T20:54:21.667+0000] {logging_mixin.py:154} INFO - Changing /opt/***/logs/dag_id=recalls_etl_v1/run_id=manual__2024-03-18T20:54:19.547344+00:00/task_id=get_raw_data permission to 509
[2024-03-18T20:54:21.674+0000] {task_command.py:416} INFO - Running <TaskInstance: recalls_etl_v1.get_raw_data manual__2024-03-18T20:54:19.547344+00:00 [running]> on host 3694d3cee1cf
[2024-03-18T20:54:21.754+0000] {taskinstance.py:1662} INFO - Exporting env vars: AIRFLOW_CTX_DAG_OWNER='***' AIRFLOW_CTX_DAG_ID='recalls_etl_v1' AIRFLOW_CTX_TASK_ID='get_raw_data' AIRFLOW_CTX_EXECUTION_DATE='2024-03-18T20:54:19.547344+00:00' AIRFLOW_CTX_TRY_NUMBER='1' AIRFLOW_CTX_DAG_RUN_ID='manual__2024-03-18T20:54:19.547344+00:00'
[2024-03-18T20:54:21.758+0000] {taskinstance.py:1937} ERROR - Task failed with exception
Traceback (most recent call last):
  File "/home/airflow/.local/lib/python3.8/site-packages/airflow/operators/python.py", line 192, in execute
    return_value = self.execute_callable()
  File "/home/airflow/.local/lib/python3.8/site-packages/airflow/operators/python.py", line 209, in execute_callable
    return self.python_callable(*self.op_args, **self.op_kwargs)
  File "/opt/airflow/dags/recalls_etl_v1.py", line 75, in get_recall_data
    df=pd.read_json('sample file.json')
  File "/home/airflow/.local/lib/python3.8/site-packages/pandas/io/json/_json.py", line 760, in read_json
    json_reader = JsonReader(
  File "/home/airflow/.local/lib/python3.8/site-packages/pandas/io/json/_json.py", line 861, in __init__
    data = self._get_data_from_filepath(filepath_or_buffer)
  File "/home/airflow/.local/lib/python3.8/site-packages/pandas/io/json/_json.py", line 917, in _get_data_from_filepath
    raise FileNotFoundError(f"File {filepath_or_buffer} does not exist")
FileNotFoundError: File sample file.json does not exist
[2024-03-18T20:54:21.778+0000] {taskinstance.py:1400} INFO - Marking task as FAILED. dag_id=recalls_etl_v1, task_id=get_raw_data, execution_date=20240318T205419, start_date=20240318T205421, end_date=20240318T205421
[2024-03-18T20:54:21.790+0000] {standard_task_runner.py:104} ERROR - Failed to execute job 18 for task get_raw_data (File sample file.json does not exist; 119)
[2024-03-18T20:54:21.828+0000] {local_task_job_runner.py:228} INFO - Task exited with return code 1
[2024-03-18T20:54:21.854+0000] {taskinstance.py:2778} INFO - 0 downstream tasks scheduled from follow-on schedule check
