[2024-03-18T23:45:27.466+0000] {logging_mixin.py:154} INFO - Changing /opt/***/logs/dag_id=recalls_etl_v1/run_id=manual__2024-03-18T23:45:25.387765+00:00/task_id=get_raw_data permission to 509
[2024-03-18T23:45:27.502+0000] {logging_mixin.py:154} INFO - Changing /opt/***/logs/dag_id=recalls_etl_v1/run_id=manual__2024-03-18T23:45:25.387765+00:00/task_id=get_raw_data permission to 509
[2024-03-18T23:45:27.537+0000] {taskinstance.py:1159} INFO - Dependencies all met for dep_context=non-requeueable deps ti=<TaskInstance: recalls_etl_v1.get_raw_data manual__2024-03-18T23:45:25.387765+00:00 [queued]>
[2024-03-18T23:45:27.547+0000] {taskinstance.py:1159} INFO - Dependencies all met for dep_context=requeueable deps ti=<TaskInstance: recalls_etl_v1.get_raw_data manual__2024-03-18T23:45:25.387765+00:00 [queued]>
[2024-03-18T23:45:27.548+0000] {taskinstance.py:1361} INFO - Starting attempt 1 of 1
[2024-03-18T23:45:27.563+0000] {taskinstance.py:1382} INFO - Executing <Task(PythonOperator): get_raw_data> on 2024-03-18 23:45:25.387765+00:00
[2024-03-18T23:45:27.568+0000] {standard_task_runner.py:57} INFO - Started process 2774 to run task
[2024-03-18T23:45:27.571+0000] {standard_task_runner.py:84} INFO - Running: ['***', 'tasks', 'run', 'recalls_etl_v1', 'get_raw_data', 'manual__2024-03-18T23:45:25.387765+00:00', '--job-id', '50', '--raw', '--subdir', 'DAGS_FOLDER/recalls_etl_v1.py', '--cfg-path', '/tmp/tmpes8ta8y3']
[2024-03-18T23:45:27.572+0000] {standard_task_runner.py:85} INFO - Job 50: Subtask get_raw_data
[2024-03-18T23:45:27.621+0000] {logging_mixin.py:154} INFO - Changing /opt/***/logs/dag_id=recalls_etl_v1/run_id=manual__2024-03-18T23:45:25.387765+00:00/task_id=get_raw_data permission to 509
[2024-03-18T23:45:27.629+0000] {task_command.py:416} INFO - Running <TaskInstance: recalls_etl_v1.get_raw_data manual__2024-03-18T23:45:25.387765+00:00 [running]> on host 3694d3cee1cf
[2024-03-18T23:45:27.718+0000] {taskinstance.py:1662} INFO - Exporting env vars: AIRFLOW_CTX_DAG_OWNER='***' AIRFLOW_CTX_DAG_ID='recalls_etl_v1' AIRFLOW_CTX_TASK_ID='get_raw_data' AIRFLOW_CTX_EXECUTION_DATE='2024-03-18T23:45:25.387765+00:00' AIRFLOW_CTX_TRY_NUMBER='1' AIRFLOW_CTX_DAG_RUN_ID='manual__2024-03-18T23:45:25.387765+00:00'
[2024-03-18T23:45:27.752+0000] {taskinstance.py:1937} ERROR - Task failed with exception
Traceback (most recent call last):
  File "/home/airflow/.local/lib/python3.8/site-packages/airflow/operators/python.py", line 192, in execute
    return_value = self.execute_callable()
  File "/home/airflow/.local/lib/python3.8/site-packages/airflow/operators/python.py", line 209, in execute_callable
    return self.python_callable(*self.op_args, **self.op_kwargs)
  File "/opt/airflow/dags/recalls_etl_v1.py", line 80, in get_recall_data
    df.to_csv(raw_output_path, index=False)
  File "/home/airflow/.local/lib/python3.8/site-packages/pandas/core/generic.py", line 3772, in to_csv
    return DataFrameRenderer(formatter).to_csv(
  File "/home/airflow/.local/lib/python3.8/site-packages/pandas/io/formats/format.py", line 1186, in to_csv
    csv_formatter.save()
  File "/home/airflow/.local/lib/python3.8/site-packages/pandas/io/formats/csvs.py", line 240, in save
    with get_handle(
  File "/home/airflow/.local/lib/python3.8/site-packages/pandas/io/common.py", line 737, in get_handle
    check_parent_directory(str(handle))
  File "/home/airflow/.local/lib/python3.8/site-packages/pandas/io/common.py", line 600, in check_parent_directory
    raise OSError(rf"Cannot save file into a non-existent directory: '{parent}'")
OSError: Cannot save file into a non-existent directory: '/opt/***/data/raw'
[2024-03-18T23:45:27.771+0000] {taskinstance.py:1400} INFO - Marking task as FAILED. dag_id=recalls_etl_v1, task_id=get_raw_data, execution_date=20240318T234525, start_date=20240318T234527, end_date=20240318T234527
[2024-03-18T23:45:27.785+0000] {standard_task_runner.py:104} ERROR - Failed to execute job 50 for task get_raw_data (Cannot save file into a non-existent directory: '/opt/***/data/raw'; 2774)
[2024-03-18T23:45:27.824+0000] {local_task_job_runner.py:228} INFO - Task exited with return code 1
[2024-03-18T23:45:27.852+0000] {taskinstance.py:2778} INFO - 0 downstream tasks scheduled from follow-on schedule check
