[2024-03-18T23:28:05.321+0000] {logging_mixin.py:154} INFO - Changing /opt/***/logs/dag_id=recalls_etl_v1/run_id=manual__2024-03-18T23:28:03.491910+00:00/task_id=get_raw_data permission to 509
[2024-03-18T23:28:05.354+0000] {logging_mixin.py:154} INFO - Changing /opt/***/logs/dag_id=recalls_etl_v1/run_id=manual__2024-03-18T23:28:03.491910+00:00/task_id=get_raw_data permission to 509
[2024-03-18T23:28:05.389+0000] {taskinstance.py:1159} INFO - Dependencies all met for dep_context=non-requeueable deps ti=<TaskInstance: recalls_etl_v1.get_raw_data manual__2024-03-18T23:28:03.491910+00:00 [queued]>
[2024-03-18T23:28:05.401+0000] {taskinstance.py:1159} INFO - Dependencies all met for dep_context=requeueable deps ti=<TaskInstance: recalls_etl_v1.get_raw_data manual__2024-03-18T23:28:03.491910+00:00 [queued]>
[2024-03-18T23:28:05.402+0000] {taskinstance.py:1361} INFO - Starting attempt 1 of 1
[2024-03-18T23:28:05.420+0000] {taskinstance.py:1382} INFO - Executing <Task(PythonOperator): get_raw_data> on 2024-03-18 23:28:03.491910+00:00
[2024-03-18T23:28:05.425+0000] {standard_task_runner.py:57} INFO - Started process 2491 to run task
[2024-03-18T23:28:05.429+0000] {standard_task_runner.py:84} INFO - Running: ['***', 'tasks', 'run', 'recalls_etl_v1', 'get_raw_data', 'manual__2024-03-18T23:28:03.491910+00:00', '--job-id', '43', '--raw', '--subdir', 'DAGS_FOLDER/recalls_etl_v1.py', '--cfg-path', '/tmp/tmp9zg8f266']
[2024-03-18T23:28:05.430+0000] {standard_task_runner.py:85} INFO - Job 43: Subtask get_raw_data
[2024-03-18T23:28:05.483+0000] {logging_mixin.py:154} INFO - Changing /opt/***/logs/dag_id=recalls_etl_v1/run_id=manual__2024-03-18T23:28:03.491910+00:00/task_id=get_raw_data permission to 509
[2024-03-18T23:28:05.491+0000] {task_command.py:416} INFO - Running <TaskInstance: recalls_etl_v1.get_raw_data manual__2024-03-18T23:28:03.491910+00:00 [running]> on host 3694d3cee1cf
[2024-03-18T23:28:05.573+0000] {taskinstance.py:1662} INFO - Exporting env vars: AIRFLOW_CTX_DAG_OWNER='***' AIRFLOW_CTX_DAG_ID='recalls_etl_v1' AIRFLOW_CTX_TASK_ID='get_raw_data' AIRFLOW_CTX_EXECUTION_DATE='2024-03-18T23:28:03.491910+00:00' AIRFLOW_CTX_TRY_NUMBER='1' AIRFLOW_CTX_DAG_RUN_ID='manual__2024-03-18T23:28:03.491910+00:00'
[2024-03-18T23:28:05.576+0000] {taskinstance.py:1937} ERROR - Task failed with exception
Traceback (most recent call last):
  File "/home/airflow/.local/lib/python3.8/site-packages/airflow/operators/python.py", line 192, in execute
    return_value = self.execute_callable()
  File "/home/airflow/.local/lib/python3.8/site-packages/airflow/operators/python.py", line 209, in execute_callable
    return self.python_callable(*self.op_args, **self.op_kwargs)
  File "/opt/airflow/dags/recalls_etl_v1.py", line 72, in get_recall_data
    df = pd.read.json(file)
AttributeError: module 'pandas' has no attribute 'read'
[2024-03-18T23:28:05.590+0000] {taskinstance.py:1400} INFO - Marking task as FAILED. dag_id=recalls_etl_v1, task_id=get_raw_data, execution_date=20240318T232803, start_date=20240318T232805, end_date=20240318T232805
[2024-03-18T23:28:05.603+0000] {standard_task_runner.py:104} ERROR - Failed to execute job 43 for task get_raw_data (module 'pandas' has no attribute 'read'; 2491)
[2024-03-18T23:28:05.642+0000] {local_task_job_runner.py:228} INFO - Task exited with return code 1
[2024-03-18T23:28:05.667+0000] {taskinstance.py:2778} INFO - 0 downstream tasks scheduled from follow-on schedule check
